Workbook

Sheet 總數
A1: 機型 | B1: 底座 | C1: 工作台 | D1: 橫樑 | E1: 立柱 | F1: 機頭 | G1: 定樑
A2: AHC-X31 | D2: =橫樑!I2
A3: AHC-X36 | D3: =橫樑!I3
A4: AHC-X46 | D4: =橫樑!I4
A5: AMZ4265 | C5: =工作台!#REF!
A6: AMZ5350 | D6: =橫樑!#REF!
A7: HB-3190 | C7: =工作台!#REF!
A8: HCMC-1270 | F8: =機頭!F3
A9: HEP2150 | B9: =底座!F5 | C9: =工作台!J3 | D9: =橫樑!I7
A10: HSA-216 | C10: =工作台!J4
A11: HEP-2150(一體式-標準) | B11: =底座!H6
A12: HSA-216(一體式-標準) | B12: =底座!H7
A13: HEP-216(一體式-100H) | B13: =底座!H8
A14: HEP-216(一體式-200H) | B14: =底座!H9
A15: HEP3150 | B15: =底座!H10 | C15: =工作台!J5
A16: HEP-3150(一體式-Z-80) | B16: =底座!H11
A17: HEP-3150(一體式-標準) | B17: =底座!H12
A18: HSA-316(一體式-標準) | B18: =底座!H13
A19: HSA-316(一體式-100H) | B19: =底座!H14
A20: HSA-316(一體式-200H) | B20: =底座!H15
A21: HSA-316 | C21: =工作台!J6
A22: HEP-1420立柱 | E22: =立柱!#REF!
A23: HEP-1520立柱 | E23: =立柱!#REF!
A24: HEP-1620立柱 | E24: =立柱!#REF!
A25: HEP-1720立柱 | E25: =立柱!#REF!
A26: HSA-2212 | B26: =底座!H2 | C26: =工作台!J43
A27: HSA-2212(一體式-200H) | B27: =底座!H3
A28: HSA-3212 | B28: =底座!H4 | C28: =工作台!J44
A29: HSA-220 | B29: =底座!H16 | C29: =工作台!J7
A30: HSA-320 | B30: =底座!H17 | C30: =工作台!J8
A31: HSA-320_NEO | B31: =底座!H18 | C31: =工作台!J9
A32: HSA323 | B32: =底座!H19 | C32: =工作台!J10
A33: HSA328 | B33: =底座!H20 | C33: =工作台!J11
A34: HSA327 | B34: =底座!H21
A35: HSA-420 | B35: =底座!H22 | C35: =工作台!J12 | D35: 0
A36: HSA423_NEO | B36: =底座!H24 | C36: =工作台!J13 | D36: 0
A37: HSA423 | B37: =底座!H23 | C37: =工作台!J14 | D37: 0
A38: HAS-4265 | E38: =立柱!#REF!
A39: HSA427 | B39: =底座!H25 | D39: 0
A40: HSA428 | B40: =底座!H26 | C40: =工作台!J15 | D40: 0
...

Sheet 底座
A1: 品號 | B1: 機型 | C1: 素材 | D1: 製程4 | E1: 製程3成品 | F1: 研磨成品 | G1: 報廢品 | H1: 總數 | I1: 預扣件 | J1: 報廢品.1 | K1: 研-09-09 | L1: Unnamed: 11 | M1: Unnamed: 12 | N1: 已開單 | O1: Unnamed: 14
A2: 8810001322 | B2: HSA-2212 | C2: 0 | D2: 1 | E2: 1 | F2: 0 | H2: 2 | K2: 3
A3: 8810001323 | B3: HSA-2212(一體式-200H) | C3: 0 | D3: 0 | E3: 0 | F3: 0
A4: 8810001324 | B4: HSA-3212 | C4: 0 | D4: 0 | E4: 0 | F4: 0 | H4: 0
A5: 8810001205 | B5: HEP-2150 | C5: 0 | D5: 0 | E5: 0 | F5: 0 | L5: HEP-2150
A6: 8810001442 | B6: HEP-2150(一體式-標準) | C6: 0 | D6: 0 | E6: 0 | F6: 0
A7: 8810001490 | B7: HSA-216(一體式-標準) | C7: 0 | D7: 0 | E7: 0 | F7: 4 | H7: 4 | K7: 4
A8: 8810001492 | B8: HEP-216(一體式-100H) | C8: 0 | D8: 0 | E8: 0 | F8: 0
A9: 8810001494 | B9: HEP-216(一體式-200H) | C9: 0 | D9: 0 | E9: 0 | F9: 0
A10: 8810001080 | B10: HEP-3150 | C10: 0 | D10: 0 | E10: 0 | F10: 0 | L10: HEP-3150
A11: 8810001445 | B11: HEP-3150(一體式-Z-80) | C11: 0 | D11: 0 | E11: 0 | F11: 0
A12: 8810001443 | B12: HEP-3150(一體式-標準) | C12: 0 | D12: 0 | E12: 0 | F12: 0
A13: 8810001491 | B13: HSA-316(一體式-標準) | C13: 0 | D13: 0 | E13: 0 | F13: 2 | H13: 4 | K13: 4
A14: 8810001493 | B14: HSA-316(一體式-100H) | C14: 0 | D14: 0 | E14: 0 | F14: 0
A15: 8810001495 | B15: HSA-316(一體式-200H) | C15: 0 | D15: 0 | E15: 0 | F15: 0
A16: 8810001421 | B16: HSA-220 | C16: 0 | D16: 0 | E16: 0 | F16: 0 | L16: HSA-220
A17: 8810001422 | B17: HSA-320 | C17: 0 | D17: 0 | E17: 0 | F17: 0 | L17: HSA-320 | N17: 2
A18: 8810001534 | B18: HSA-320_NEO | C18: 0 | D18: 0 | E18: 0 | F18: 0
A19: 8810001316 | B19: HSA-323 | C19: 0 | D19: 0 | E19: 0 | F19: 1 | L19: HSA323 | M19: M4:5.5HR,M3:32HR
A20: 8810001425 | B20: HSA-328 | C20: 0 | D20: 0 | E20: 1 | F20: 0 | L20: HSA328
A21: 8810001317 | B21: HSA-327 | C21: 0 | D21: 0 | E21: 0 | F21: 0 | H21: 1 | I21: 0 | L21: HSA327
A22: 8810001423 | B22: HSA-420 | C22: 0 | D22: 0 | E22: 0 | F22: 0 | H22: 1 | L22: HSA-420 | N22: 1
A23: 8810001277 | B23: HSA-423 | C23: 1 | D23: 0 | E23: 1 | F23: 0 | H23: 2 | K23: 2 | L23: HSA423 | M23: M4:6.5HR，M3:46.5HR | N23: 1
A24: 8810001250 | B24: HSA423_NEO | C24: 0 | D24: 0 | E24: 0 | F24: 0
A25: 8810001278 | B25: HSA-427 | C25: 1 | D25: 0 | E25: 0 | F25: 0 | H25: 0 | L25: HSA427
A26: 8810001252 | B26: HSA-428 | C26: 0 | D26: 0 | E26: 0 | F26: 0 | L26: HSA428
A27: 8810001359 | B27: HSA-523 | C27: 0 | D27: 0 | E27: 0 | F27: 0 | L27: HSA-523
A28: 8810001355 | B28: HSA-527 | C28: 0 | D28: 0 | E28: 0 | F28: 0 | H28: 0 | L28: HSA-527
A29: 8810001248 | B29: HSA-528 | C29: 0 | D29: 0 | E29: 0 | F29: 0 | H29: 0 | L29: HSA-528 | M29: 12/10 庫存已扣 | N29: 1
A30: 8810001265 | B30: HSA-536 | C30: 0 | D30: 0 | E30: 1 | F30: 0 | H30: 1 | L30: HSA536 | M30: 3/29興隆興入1台
A31: 8810001409 | B31: HSA-623主底座 | C31: 0 | D31: 0 | E31: 0 | F31: 0
A32: 8810001336 | B32: HSA-623副底座 | C32: 0 | D32: 0 | E32: 1 | F32: 0 | H32: 1
A33: 8810001334 | B33: HSA-627主底座 | C33: 0 | D33: 0 | E33: 1 | F33: 0 | H33: 1
A34: 8810001336 | B34: HSA-627副底座 | C34: 0 | D34: 0 | E34: 0 | F34: 0
A35: 8810001352 | B35: HSA-628主底座 | C35: 0 | D35: 0 | E35: 0 | F35: 0 | M35: M3:45.5HR
A36: 8810001353 | B36: HSA-628副底座 | C36: 0 | D36: 0 | E36: 0 | F36: 0 | M36: M3:19HR
A37: 8810001367 | B37: HSA-636主底座 | C37: 0 | D37: 0 | E37: 0
A38: 8810001366 | B38: HSA-636副底座 | C38: 0 | D38: 0 | E38: 0
A39: 8810001400 | B39: HSA-728主底座 | C39: 0 | D39: 0 | E39: 0
A40: 8810001401 | B40: HSA-728副底座 | C40: 0 | D40: 0 | E40: 0
...

Sheet 工作台
A1: 品號 | B1: 機型 | C1: 素材 | D1: 製程1 | E1: 製程2 | F1: 製程3 | G1: 製程4 | H1: 成品 | I1: Unnamed: 8 | J1: 總數 | K1: 預扣件 | L1: 報廢品 | M1: Unnamed: 12 | N1: Unnamed: 13 | O1: Unnamed: 14 | P1: 已開單 | Q1: Unnamed: 16
B2: AMZ-4265 | C2: 1 | D2: 0 | E2: 0 | F2: 0 | G2: 0 | H2: 0 | J2: 1
A3: 8813000949 | B3: HEP-2150 | C3: 2 | D3: 0 | E3: 0 | F3: 0 | G3: 0 | H3: 0 | J3: 2
A4: 8813001304 | B4: HSA-216 | C4: 0 | D4: 0 | E4: 0 | F4: 0 | G4: 5 | H4: 5 | I4: 5 | J4: 5 | L4: 0
A5: 8813000963 | B5: HEP3150 | C5: 0 | D5: 0 | E5: 0 | H5: 0 | P5: 2
A6: 8813001305 | B6: HSA-316 | C6: 1 | D6: 0 | E6: 0 | F6: 0 | G6: 1 | H6: 1 | I6: 4 | J6: 4 | L6: 0 | N6: W1:10HR,W2:27HR,W3:5.5HR
A7: 8813001063 | B7: HSA-220 | C7: 0 | D7: 0 | E7: 0 | H7: 0
A8: 8813001071 | B8: HSA-320 | C8: 1 | D8: 0 | E8: 0 | H8: 0 | L8: 0 | N8: 自修T溝尺寸破工公差(第三區-噴漆)-12/22 | P8: 3 | Q8: 12/10 庫存已扣
A9: 8813001377 | B9: HSA-320_NEO | C9: 0 | D9: 0 | E9: 0 | H9: 0
A10: 8813001120 | B10: HSA-323 | C10: 0 | D10: 0 | E10: 2 | F10: 0 | G10: 0 | H10: 1 | I10: 2 | J10: 1 | K10: 0 | L10: 0 | N10: W1:18HR,W2:40HR,W3:4.5HR
A11: 8813001187 | B11: HSA-328 | C11: 0 | D11: 0 | E11: 0 | H11: 0
A12: 8813001085 | B12: HSA-420 | C12: 0 | D12: 0 | E12: 0 | F12: 0 | G12: 0 | H12: 0 | I12: 1
A13: 8813001089 | B13: HSA-423_NEO | C13: 0 | D13: 0 | E13: 0 | H13: 0
A14: 8813001079 | B14: HSA-423 | C14: 0 | D14: 0 | E14: 0 | F14: 0 | G14: 1 | H14: 0 | I14: 2 | J14: 3 | L14: 1 | N14: W1:21HR,W2:46HR,W3:5.5HR | O14: (改單-3溝X向定位溝)
A15: 8813001060 | B15: HSA-428 | C15: 0 | D15: 0 | E15: 0 | H15: 0
B16: HSA4320(VF) | C16: 1 | D16: 0 | E16: 0 | F16: 0 | G16: 0 | H16: 0 | J16: 1
A17: 8813001121 | B17: HSA-436 | C17: 0 | D17: 0 | E17: 0 | H17: 0
A18: 8813001147 | B18: HSA-523 | C18: 0 | D18: 0 | E18: 0 | F18: 0 | G18: 0 | H18: 1 | I18: 0 | J18: 2 | N18: 12/10 庫存已扣 | P18: 2
A19: 8813001061 | B19: HSA-528 | C19: 0 | D19: 0 | E19: 0 | F19: 0 | G19: 0 | H19: 0 | J19: 0 | P19: 2
A20: 8813001068 | B20: HSA-536 | C20: 0 | D20: 0 | E20: 0 | F20: 0 | G20: 1 | H20: 0 | I20: 1
A21: 8813001132 | B21: HSA-623 | C21: 1 | D21: 0 | E21: 0 | H21: 0
A22: 8813001056 | B22: HSA-628 | C22: 0 | D22: 0 | E22: 0 | H22: 0
A23: 8813001086 | B23: HSA-636 | C23: 0 | D23: 0 | E23: 0 | H23: 0 | L23: 0
A24: 8813001171 | B24: HSA-728 | C24: 0 | D24: 0 | E24: 0 | H24: 0
A25: 8813001152 | B25: HSA-736 | C25: 0 | D25: 0 | E25: 0 | H25: 0
A26: 8813001252 | B26: SW-216 | C26: 1 | D26: 0 | E26: 0 | F26: 0 | G26: 0 | H26: 1 | I26: 1 | J26: 1
A27: 8813001178 | B27: SW-2616 | C27: 0 | D27: 0 | E27: 0 | G27: 0 | H27: 0 | O27: 此2+1台為舊鑄件(螺姆孔大小設變) | P27: 1
A28: 8813001246 | B28: SW-220 | C28: 0 | D28: 0 | E28: 0 | G28: 0 | H28: 0
A29: 8813001254 | B29: SW-316 | C29: 2 | D29: 0 | E29: 1 | F29: 0 | G29: 0 | H29: 0 | J29: 3 | L29: 0 | N29: W1:17HR,W2:22HR,W4:5.5HR,W5:9.5HR | P29: -
A30: 8813001247 | B30: SW-320 | C30: 0 | D30: 0 | E30: 0 | F30: 0 | G30: 3 | H30: 3 | I30: 3 | L30: 0 | P30: 2
A31: 8813001244 | B31: SW-323 | C31: 0 | D31: 0 | E31: 0 | F31: 0 | G31: 1 | H31: 1 | I31: 1 | N31: H08000573*1做完知會蔡高專。
A32: 8813001256 | B32: SW-326 | C32: 0 | D32: 0 | E32: 0 | G32: 0 | H32: 0
A33: 8813001255 | B33: SW-416 | C33: 0 | D33: 0 | E33: 0 | F33: 0 | G33: 2 | H33: 2 | I33: 2
A34: 8813001248 | B34: SW-420 | C34: 0 | D34: 0 | E34: 0 | G34: 0 | H34: 0
A35: 8813001261 | B35: SW-423 | C35: 0 | D35: 0 | E35: 0 | F35: 0 | G35: 1 | H35: 1 | I35: 1 | J35: 1 | N35: W1:21HR,W2:43HR,W4:5.5HR,W5:10HR | P35: 1
A36: 8813001353 | B36: SW-426 | C36: 0 | D36: 0 | E36: 0 | G36: 0 | H36: 0
B37: SW-4350 | C37: 0 | D37: 0 | E37: 0 | F37: 1 | G37: 0 | H37: 0 | I37: 1
A38: 8813001262 | B38: SW-523 | C38: 0 | D38: 0 | E38: 0 | G38: 0 | H38: 0
A39: 8813001115 | B39: SW-623 | C39: 0 | D39: 1 | E39: 0 | F39: 0 | G39: 0 | H39: 0 | J39: 1 | L39: 0 | N39: W1:25HR,W2:60HR,W4:7.5HR,W5:12HR
A40: 8813001078 | B40: SW-526 | C40: 0 | D40: 0 | E40: 0 | G40: 0 | H40: 0 | N40: 1台傑浩
...

Sheet 橫樑
A1: 品號 | B1: 機型 | C1: 素材 | D1: 製程7 | E1: 製程6 | F1: 製程5(成品) | G1: 研磨成品 | H1: 報廢品 | I1: 總數 | J1: 預扣件 | K1: 報廢品.1 | L1: Unnamed: 11 | M1: 研-09-09 | N1: Unnamed: 13 | O1: Unnamed: 14 | P1: 已開單
A2: 8817000571 | B2: AHC-X31 | C2: 0 | E2: 0 | F2: 0 | G2: 0 | L2: 5270L | N2: AHC-X31
A3: 8817000566 | B3: AHC-X36 | C3: 0 | E3: 3 | F3: 0 | G3: 1 | I3: 4 | L3: 5770L | M3: 1 | N3: AHC-X36
A4: 8817000581 | B4: AHC-X46 | C4: 0 | E4: 0 | F4: 1 | G4: 0 | I4: 1 | L4: 6770L | N4: AHC-X46
B5: AMZX350(5350) | C5: 1
B6: VF4320(HSA4320) | C6: 0 | G6: 1
A7: 8817000399 | B7: HEP2150 | C7: 0 | E7: 0 | F7: 0 | G7: 0
A8: 8817000551 | B8: HSA-X20 | C8: 0 | E8: 0 | F8: 0 | G8: 0 | I8: 1 | L8: 3810L | M8: 1 | N8: HSA-X20 | O8: 12/10 庫存已扣 | P8: 2
A9: 8817000552 | B9: HSA-X20EAY | C9: 0 | E9: 0 | F9: 0 | G9: 0 | L9: 4150L | N9: HSA-X20EAY | P9: 2
A10: 8817000491 | B10: HSA-X23 | C10: 2 | E10: 0 | F10: 0 | G10: 3 | I10: 6 | L10: 3960L | M10: 3 | N10: HSA-X23 | O10: M6:16HR，M5:22HR
A11: 8817000517 | B11: HSA-X23EAY | C11: 1 | E11: 0 | F11: 0 | G11: 0 | H11: 0 | I11: 2 | L11: 4650L | M11: 3 | N11: HSA-X23EAY | O11: M6:18HR，M5:37HR
A12: 8817000483 | B12: HSA-X27 | C12: 0 | E12: 0 | F12: 0 | G12: 5 | J12: 0 | K12: 0 | L12: 台典成品*1,4600L | M12: 6 | N12: HSA-X27
A13: 8817000518 | B13: HSA-X27EAY | C13: 2 | E13: 0 | F13: 0 | G13: 0 | I13: 3 | K13: 0 | L13: 5150-5130 | M13: 2 | N13: HSA-X27EAY | O13: M6-1*3 OK
A14: 8817000547 | B14: HSA-X32 | C14: 0 | E14: 0 | F14: 0 | G14: 2 | L14: 5050L | M14: 2 | N14: HSA-X32
A15: 8817000548 | B15: HSA-X32EAY | C15: 0 | E15: 0 | F15: 0 | G15: 0 | L15: 5600L | M15: 1 | N15: HSA-X32EAY
A16: 8817000568 | B16: HSA-X36EAY | C16: 0 | E16: 0 | F16: 0 | G16: 0 | L16: 5950L | N16: HSA-X36EAY | O16: 隆升借放*4-有入帳 | P16: 1
A17: 8817000485 | B17: HSA-X36 | C17: 0 | E17: 0 | F17: 0 | G17: 5 | K17: ` | L17: 5600L | M17: 5 | N17: HSA-X36
A18: 8817000635 | B18: TGV-106 | C18: 0 | E18: 0 | F18: 0 | G18: 0
A19: 8817000441 | B19: HSA-X23_NEO | C19: 0 | D19: 0 | E19: 0 | F19: 0 | G19: 0
A20: 8817000650 | B20: HSA-X20_NEO | C20: 0 | D20: 0 | E20: 0 | F20: 0 | G20: 0

Sheet 立柱
A1: 品號 | B1: 機型 | C1: 素材 | D1: 半成品 | E1: 成品(銑) | F1: 成品(研) | G1: 總數 | H1: 報廢 | I1: Unnamed: 8 | J1: Unnamed: 9 | K1: Unnamed: 10 | L1: Unnamed: 11 | M1: Unnamed: 12
B2: 5BC-4300 | C2: 1 | E2: 2
B3: HEP2150-1720 | E3: 2
B4: HEP2150-1620 | C4: 2 | D4: 2
B5: HSA4265 | C5: 2 | D5: 0 | E5: 0
A6: 8811001091 | B6: LG-800 | C6: 6 | D6: 3 | E6: 0 | F6: 0 | G6: 9
A7: 8811001273 | B7: LG-1370 | C7: 0 | D7: 0 | E7: 0 | F7: 0
A8: 8811001013 | B8: MVP-860 | F8: 0
A9: 8811001077 | B9: MVP-860+200H | C9: 0 | D9: 0 | E9: 0 | F9: 0 | G9: 0
A10: 8811001393 | B10: MVP-11 | C10: 0 | D10: 0 | E10: 0 | F10: 0 | G10: 0
A11: 8811001536 | B11: A10 | C11: 0 | D11: 0 | E11: 0 | F11: 0
A12: 8811001338 | B12: S-PLUS 8 | C12: 0 | D12: 0 | F12: 0
A13: 8811001526 | B13: S8 | C13: 1 | D13: 0 | E13: 0 | F13: 0 | G13: 1
A14: 8811001616 | B14: LG-1370-NEO | C14: 3 | D14: 0 | E14: 0 | F14: 0 | G14: 0 | H14: 0 | K14: M1:14.5HR | L14: M2:7.5HR | M14: M7:2.HR
A15: 8811001625 | B15: LG-1370-NEO+200H | C15: 0 | D15: 0 | E15: 0 | F15: 0 | G15: 0 | H15: 0
A16: 8811001619 | B16: LG-1000-NEO | C16: 1 | D16: 0 | E16: 0 | F16: 0
A17: 8811001623 | B17: LG-1000-NEO+200H | C17: 1 | D17: 0 | E17: 0 | F17: 0

Sheet 機頭
A1: 項次 | B1: 機型 | C1: 素材 | D1: 半成品 | E1: 成品 | F1: 總數
A2: 1 | B2: PRO-1000 | D2: 0 | E2: 0 | F2: =C2+D2+E2
A3: 2 | B3: HCMC-1270 | D3: 0 | E3: 0 | F3: =C3+D3+E3

Sheet 橫樑滑座
A1: 項次 | B1: 機型 | C1: 素材 | D1: 成品 | E1: 總數
A2: 1 | B2: DW | E2: 0

Sheet 定樑
B1: 機型 | C1: 素材 | D1: 成品 | E1: 總數
B2: VW-X340 | C2: 1 | E2: 1

Sheet 報廢鑄件
A1: 機型 | B1: 數量 | C1: 報廢原因 | D1: 廠商
A2: HEP-2150工作台 | B2: 0 | C2: 加工溝寬錯誤*1(W2)(加工問題) | D2: 楊鋼
A3: HSA-420工作台 | B3: 0 | C3: NG*1(W5螺姆座Y軸錯誤)(成品)(加工問題) | D3: 永棧
A4: SW-426工作台 | B4: 0 | C4: NG*1-W2(加工問題) | D4: 永棧
A5: HB-3190工作台 | B5: 0 | C5: 舊鑄件 | D5: 永棧
A6: HEP-2150橫樑 | B6: 0 | C6: NG*1(加工問題) | D6: 永棧
